Workbook
Name functions: Lists!$B$11:$I$11
Name verticals: Lists!$B$1:$F$1
Name research_status: Lists!$B$4:$E$4
Name tiers: Lists!$B$3:$D$3
Name relationship_source: Lists!$B$13:$H$13
Name persona_status: Lists!$B$7:$G$7
Name signal_types: Lists!$B$2:$G$2
Name yes_no: Lists!$B$10:$C$10
Name account_names: Accounts!$B$2:$B$41
Name owners: Lists!$B$9:$F$9
Name seniority: Lists!$B$12:$G$12
Name outreach_status: Lists!$B$5:$F$5
Name meeting_status: Lists!$B$6:$G$6
Name activity_types: Lists!$B$8:$I$8

Sheet Form Responses 1
A1: Timestamp | B1: Show Day | C1: Time Block | D1: Account | E1: Persona Name | F1: Title | G1: Channel | H1: Meeting Type | I1: Location | J1: Interest (1-5) | K1: Urgency (1-5) | L1: Influence (1-5) | M1: Use-Case Fit (1-5) | N1: Requested Asset | O1: Need Primo? | P1: Next Step | Q1: Owner | R1: Due Date | S1: Follow-Up Template | T1: Outcome | U1: Notes
A2: 46106.495 | B2: Day 1 | C2: 10:00-12:00 | D2: Danone | E2: Test Contact | F2: VP Supply Chain | G2: Booth | H2: Discovery | I2: MODEX Floor | J2: 5 | K2: 4 | L2: 5 | M2: 5 | N2: Infographic | O2: Yes | P2: Send Danone Infographic | Q2: Jake | R2: 46107 | T2: Qualified | U2: Test submission from setup validation

Sheet README
A1: MODEX Campaign RevOps Engine
A2: Purpose
A3: Run the MODEX meeting campaign for Jake / FreightRoll in one place: rank accounts, research personas, track intros and outreach, and manage booked meetings.
A5: How to use
A6: 1. Start in Accounts: update scores, statuses, current motion, next actions, and due dates.
A7: 2. Add named targets in Personas as you identify them. The sheet pulls the account score automatically.
A8: 3. Log every touch in Activities. If it happened, log it. CRM discipline beats optimism theater.
A9: 4. Move real conversations into Meetings and tag whether Primo will join for social proof.
A10: 5. Use Dashboard in standups to see pipeline, coverage gaps, and which accounts need executive air cover.
A13: Scoring logic
A14: Priority Score is a weighted 0-100 score built from ICP fit, MODEX signal, Primo story fit, warm intro strength, strategic value, and meeting ease.
A15: Weights and tier cutoffs live on the hidden Lists sheet so you can tune the machine without rebuilding formulas.
A17: Color guide
A18: Blue text / pale blue fill | B18: Inputs you should update
A19: Green text / pale green fill | B19: Linked or imported reference fields
A20: Black text / white fill | B20: Formulas and outputs
A21: Gray text / gray fill | B21: Static labels and constants
A22: Purple fill | B22: Control logic
A25: Source note
A26: Seed account signals came from official MODEX 2026 pages and the official past-attendee PDF. URLs are stored in the Accounts sheet for easy fact checking.
A28: New in Phase 3+
A29: Hunt Plan | B29: Account-by-account hunting order, title lanes, proof assets, and timing.
A30: Search Strings | B30: Repeatable LinkedIn / Sales Nav / Google queries for persona discovery.
A31: Outreach Waves | B31: Wave-based operating cadence to sequence warm intros, must-book targets, and opportunistic accounts.
A32: Meeting Briefs | B32: Fast pre-meeting prep with why-now angle, likely pains, and asset checklist.
A34: UI/UX update | B34: Accounts and Personas were refactored into compact operating views: filters on, panes frozen, detail columns hidden, and key intelligence pulled forward so the main tabs can be run without horizontal-scroll hell.
A35: Patch Notes | B35: Use the new Actionable Intel tab to collect facility footprint, trigger events, tech-stack clues, site leaders, and carrier pain evidence before outreach.
A36: Phase 16 patch: Live Capture now pulls directly from Form Responses 1, Mobile Capture Lite mirrors Live Capture cleanly, and Follow-Up Engine uses non-circular formulas.
A37: This version is designed so intake still works even if Apps Script append behavior is imperfect in Google Sheets.
A38: Added embedded custom infographics for the Top 20 accounts plus a compact asset register and gallery. Accounts and Personas tabs were reworked to reduce horizontal scrolling.
A40: Phase 9 additions
A41: • Jake Battlecards: account-specific meeting theses, discovery questions, objections, counters, and asks.
A42: • Jake Talk Tracks: booth-safe scripts for opening, diagnosing, bridging to Primo, and closing.
A43: • Objection Map: reusable counters by objection type.
A44: • MODEX Close Plan: what a good meeting outcome looks like account by account.
A46: Phase 11 | B46: MODEX Command Sheet
A47: Phase 12 | B47: Follow-Up Engine + Follow-Up Templates
A48: New in phase 13
A49: - Live Capture tab for in-the-moment meeting notes, scoring, follow-up assignment, and due dates.
A50: - Field View tab for a no-scroll top-20 operating view with live captures, hot signals, overdue follow-ups, and last-activity dates.
...

Sheet MODEX Command Sheet
A1: MODEX Command Sheet
A2: Run-of-show for April 13–16, 2026 in Atlanta. Hall A is open 9:00 AM–5:00 PM Monday–Wednesday and 9:00 AM–1:00 PM Thursday; Halls B & C open 10:00 AM–5:00 PM Monday–Wednesday and 9:00 AM–1:00 PM Thursday. Monday keynote at 9:00 AM: Richard McPhail, The Home Depot.
A3: Sources: https://www.modexshow.com/about | https://www.modexshow.com/education
A4: Show Days | D4: Top Accounts in Rotation | G4: Leave-Behinds Ready | I4: Follow-Up Templates
A5: 4 | D5: =COUNTA('Top 20 Board'!$B$2:$B$21) -> 20 | G5: =COUNTA('Leave-Behind Index'!$A:$A)-1 -> 12 | I5: =COUNTA('Follow-Up Templates'!$A:$A)-4 -> 5
A7: Day | B7: Time Block | C7: Focus | D7: Primary Accounts | E7: Backup Accounts | F7: Hall / Anchor | G7: Primary Asset | H7: Success Criteria | I7: Status | J7: Notes
A8: Mon 4/13 | B8: 8:15–8:50 | C8: Pre-floor prep + account triage | D8: Danone; General Mills; The Home Depot | E8: Hormel Foods; JM Smucker | F8: Lobby / coffee near Hall A | G8: Top 3 leave-behinds + battlecards | H8: Jake aligned on top 6 targets before keynote | I8: Planned
A9: Mon 4/13 | B9: 9:00–10:00 | C9: Home Depot keynote intercept window | D9: The Home Depot | E9: Barnes & Noble; Kenco Logistics Services | F9: Hall A keynote area | G9: Home Depot leave-behind + battlecard | H9: Secure post-keynote intro or referral path | I9: Planned
A10: Mon 4/13 | B10: 10:00–11:30 | C10: Food & Bev wave 1 | D10: Danone; General Mills; Frito-Lay | E10: Hormel Foods; JM Smucker | F10: Hall B/C high-traffic software zones | G10: Danone / GM / Frito infographics | H10: Book 2 meetings or 3 strong follow-up paths | I10: Planned
A11: Mon 4/13 | B11: 11:30–1:00 | C11: Lunch meetings / corridor catches | D11: Danone; The Home Depot | E11: Diageo; Georgia Pacific | F11: Any seated lunch area | G11: 2 printed leave-behinds + digital gallery | H11: One sit-down meeting or scheduled follow-up | I11: Planned
A12: Mon 4/13 | B12: 1:00–3:00 | C12: Food & Bev wave 2 | D12: Diageo; Hormel Foods; JM Smucker | E12: Dawn Foods; Del Monte Foods | F12: Hall B/C | G12: Diageo / Hormel / Smucker infographics | H12: Advance 3 accounts to next step | I12: Planned
A13: Mon 4/13 | B13: 3:00–5:00 | C13: Retail / industrial wave | D13: Georgia Pacific; H-E-B; Hyundai Motor America | E13: Honda; John Deere | F13: Hall A / crossover aisles | G13: GP / H-E-B / Hyundai battlecards | H13: Log 6 quality conversations | I13: Planned
A14: Tue 4/14 | B14: 9:00–10:00 | C14: Keynote networking / AI wedge | D14: FedEx; Kenco Logistics Services | E14: IKEA; Dollar General | F14: Keynote area / foyer | G14: Kenco + FedEx one-pagers | H14: Find 2 warm referrals from ecosystem players | I14: Planned
A15: Tue 4/14 | B15: 10:00–12:00 | C15: Top-10 must-book sweep | D15: Danone; General Mills; Frito-Lay; The Home Depot | E15: Diageo; Hormel Foods | F15: Hall B/C then Hall A | G15: Top 10 leave-behinds | H15: Book 3 meetings and identify 3 alternates | I15: Planned
A16: Tue 4/14 | B16: 1:00–3:00 | C16: Manufacturing / automotive sweep | D16: Hyundai Motor America; Honda; John Deere | E16: Georgia Pacific; Del Monte Foods | F16: Hall A/B | G16: Hyundai / Honda / Deere infographics | H16: Open 2 meetings and 3 real follow-ups | I16: Planned
A17: Tue 4/14 | B17: 3:00–5:00 | C17: Retail / grocery / value channel | D17: H-E-B; Dollar General; Dollar Tree; IKEA | E17: Barnes & Noble | F17: Hall A | G17: Retail leave-behinds | H17: Find operator-level buyers and transportation leads | I17: Planned
A18: Wed 4/15 | B18: 9:00–10:00 | C18: Keynote + partner intelligence | D18: Kenco Logistics Services; Barnes & Noble | E18: FedEx | F18: Keynote area | G18: Kenco / B&N battlecards | H18: Secure ecosystem insight or referral | I18: Planned
A19: Wed 4/15 | B19: 10:00–12:00 | C19: Close-plan day: convert interest to meetings | D19: All open P1 accounts | E19: Any top-20 backup | F19: Hall B/C software zones | G19: Battlecards + calendar booking links | H19: Turn floor interest into calendar holds | I19: Planned
... A23: Thu 4/16 | B23: 11:00–1:00 | C23: Last-call triage + follow-up staging | D23: All active accounts | E23: Any missed account | F23: Exit paths / coffee / lobby | G23: Follow-up templates + notes | H23: Every quality conversation assigned a next step | I23: Planned

Sheet Live Capture
A1: Timestamp
A2: Fast capture sheet for live conversations. Log the interaction, score the signal, set the next step, and keep the floor moving.
A3: Scoring: Heat Score = Interest + Urgency + Influence + Use-Case Fit + 2 bonus if Primo proof requested. Filter for HOT / WARM when triaging post-meeting work.
A5: Capture ID | B5: Logged At | C5: Show Day | D5: Time Block | E5: Account | F5: Persona Name | G5: Title | H5: Channel | I5: Meeting Type | J5: Location | K5: Interest (1-5) | L5: Urgency (1-5) | M5: Influence (1-5) | N5: Use-Case Fit (1-5) | O5: Requested Asset | P5: Need Primo? | Q5: Next Step | R5: Owner | S5: Due Date | T5: Follow-Up Template | U5: Outcome | V5: Heat Score | W5: Band | X5: Status | Y5: Notes
A6: =IF(E6="","","LC-"&TEXT(ROW()-5,"000")) -> LC-001 | B6: {=IFERROR(IF(INDEX('Form Responses 1'!$D:$D,ROW()-4)="","",INDEX('Form Responses 1'!$A:$A,ROW()-4)),"")} -> 46106.495 | C6: {=IFERROR(IF(INDEX('Form Responses 1'!$D:$D,ROW()-4)="","",INDEX('Form Responses 1'!$B:$B,ROW()-4)),"")} -> Day 1 | D6: {=IFERROR(IF(INDEX('Form Responses 1'!$D:$D,ROW()-4)="","",INDEX('Form Responses 1'!$C:$C,ROW()-4)),"")} -> 10:00-12:00 | E6: {=IFERROR(IF(INDEX('Form Responses 1'!$D:$D,ROW()-4)="","",INDEX('Form Responses 1'!$D:$D,ROW()-4)),"")} -> Danone | F6: {=IFERROR(IF(INDEX('Form Responses 1'!$D:$D,ROW()-4)="","",INDEX('Form Responses 1'!$E:$E,ROW()-4)),"")} -> Test Contact | G6: {=IFERROR(IF(INDEX('Form Responses 1'!$D:$D,ROW()-4)="","",INDEX('Form Responses 1'!$F:$F,ROW()-4)),"")} -> VP Supply Chain | H6: {=IFERROR(IF(INDEX('Form Responses 1'!$D:$D,ROW()-4)="","",INDEX('Form Responses 1'!$G:$G,ROW()-4)),"")} -> Booth | I6: {=IFERROR(IF(INDEX('Form Responses 1'!$D:$D,ROW()-4)="","",INDEX('Form Responses 1'!$H:$H,ROW()-4)),"")} -> Discovery | J6: {=IFERROR(IF(INDEX('Form Responses 1'!$D:$D,ROW()-4)="","",INDEX('Form Responses 1'!$I:$I,ROW()-4)),"")} -> MODEX Floor | K6: {=IFERROR(IF(INDEX('Form Responses 1'!$D:$D,ROW()-4)="","",INDEX('Form Responses 1'!$J:$J,ROW()-4)),"")} -> 5 | L6: {=IFERROR(IF(INDEX('Form Responses 1'!$D:$D,ROW()-4)="","",INDEX('Form Responses 1'!$K:$K,ROW()-4)),"")} -> 4 | M6: {=IFERROR(IF(INDEX('Form Responses 1'!$D:$D,ROW()-4)="","",INDEX('Form Responses 1'!$L:$L,ROW()-4)),"")} -> 5 | N6: {=IFERROR(IF(INDEX('Form Responses 1'!$D:$D,ROW()-4)="","",INDEX('Form Responses 1'!$M:$M,ROW()-4)),"")} -> 5 | O6: {=IFERROR(IF(INDEX('Form Responses 1'!$D:$D,ROW()-4)="","",INDEX('Form Responses 1'!$N:$N,ROW()-4)),"")} -> Infographic | P6: {=IFERROR(IF(INDEX('Form Responses 1'!$D:$D,ROW()-4)="","",INDEX('Form Responses 1'!$O:$O,ROW()-4)),"")} -> Yes | Q6: {=IFERROR(IF(INDEX('Form Responses 1'!$D:$D,ROW()-4)="","",INDEX('Form Responses 1'!$P:$P,ROW()-4)),"")} -> Send Danone Infographic | R6: {=IFERROR(IF(INDEX('Form Responses 1'!$D:$D,ROW()-4)="","",INDEX('Form Responses 1'!$Q:$Q,ROW()-4)),"")} -> Jake | S6: {=IFERROR(IF(INDEX('Form Responses 1'!$D:$D,ROW()-4)="","",INDEX('Form Responses 1'!$R:$R,ROW()-4)),"")} -> 46107 | T6: {=IFERROR(IF(INDEX('Form Responses 1'!$D:$D,ROW()-4)="","",INDEX('Form Responses 1'!$S:$S,ROW()-4)),"")} | U6: {=IFERROR(IF(INDEX('Form Responses 1'!$D:$D,ROW()-4)="","",INDEX('Form Responses 1'!$T:$T,ROW()-4)),"")} -> Qualified | V6: =IF(B6="","",SUM(K6:N6)+IF(P6="Yes",2,0)) -> 21 | W6: =IF(V6="","",IF(V6>=18,"HOT",IF(V6>=14,"WARM",IF(V6>=10,"WORK","NURTURE")))) -> HOT | X6: =IF(B6="","",IF(OR(U6="Not a fit",U6="Follow later"),"Closed","Open")) -> Open | Y6: {=IFERROR(IF(INDEX('Form Responses 1'!$D:$D,ROW()-4)="","",INDEX('Form Responses 1'!$U:$U,ROW()-4)),"")} -> Test submission from setup validation
A7: =IF(E7="","","LC-"&TEXT(ROW()-5,"000")) | B7: {=IFERROR(IF(INDEX('Form Responses 1'!$D:$D,ROW()-4)="","",INDEX('Form Responses 1'!$A:$A,ROW()-4)),"")} | C7: {=IFERROR(IF(INDEX('Form Responses 1'!$D:$D,ROW()-4)="","",INDEX('Form Responses 1'!$B:$B,ROW()-4)),"")} | D7: {=IFERROR(IF(INDEX('Form Responses 1'!$D:$D,ROW()-4)="","",INDEX('Form Responses 1'!$C:$C,ROW()-4)),"")} | E7: {=IFERROR(IF(INDEX('Form Responses 1'!$D:$D,ROW()-4)="","",INDEX('Form Responses 1'!$D:$D,ROW()-4)),"")} | F7: {=IFERROR(IF(INDEX('Form Responses 1'!$D:$D,ROW()-4)="","",INDEX('Form Responses 1'!$E:$E,ROW()-4)),"")} | G7: {=IFERROR(IF(INDEX('Form Responses 1'!$D:$D,ROW()-4)="","",INDEX('Form Responses 1'!$F:$F,ROW()-4)),"")} | H7: {=IFERROR(IF(INDEX('Form Responses 1'!$D:$D,ROW()-4)="","",INDEX('Form Responses 1'!$G:$G,ROW()-4)),"")} | I7: {=IFERROR(IF(INDEX('Form Responses 1'!$D:$D,ROW()-4)="","",INDEX('Form Responses 1'!$H:$H,ROW()-4)),"")} | J7: {=IFERROR(IF(INDEX('Form Responses 1'!$D:$D,ROW()-4)="","",INDEX('Form Responses 1'!$I:$I,ROW()-4)),"")} | K7: {=IFERROR(IF(INDEX('Form Responses 1'!$D:$D,ROW()-4)="","",INDEX('Form Responses 1'!$J:$J,ROW()-4)),"")} | L7: {=IFERROR(IF(INDEX('Form Responses 1'!$D:$D,ROW()-4)="","",INDEX('Form Responses 1'!$K:$K,ROW()-4)),"")} | M7: {=IFERROR(IF(INDEX('Form Responses 1'!$D:$D,ROW()-4)="","",INDEX('Form Responses 1'!$L:$L,ROW()-4)),"")} | N7: {=IFERROR(IF(INDEX('Form Responses 1'!$D:$D,ROW()-4)="","",INDEX('Form Responses 1'!$M:$M,ROW()-4)),"")} | O7: {=IFERROR(IF(INDEX('Form Responses 1'!$D:$D,ROW()-4)="","",INDEX('Form Responses 1'!$N:$N,ROW()-4)),"")} | P7: {=IFERROR(IF(INDEX('Form Responses 1'!$D:$D,ROW()-4)="","",INDEX('Form Responses 1'!$O:$O,ROW()-4)),"")} | Q7: {=IFERROR(IF(INDEX('Form Responses 1'!$D:$D,ROW()-4)="","",INDEX('Form Responses 1'!$P:$P,ROW()-4)),"")} | R7: {=IFERROR(IF(INDEX('Form Responses 1'!$D:$D,ROW()-4)="","",INDEX('Form Responses 1'!$Q:$Q,ROW()-4)),"")} | S7: {=IFERROR(IF(INDEX('Form Responses 1'!$D:$D,ROW()-4)="","",INDEX('Form Responses 1'!$R:$R,ROW()-4)),"")} | T7: {=IFERROR(IF(INDEX('Form Responses 1'!$D:$D,ROW()-4)="","",INDEX('Form Responses 1'!$S:$S,ROW()-4)),"")} | U7: {=IFERROR(IF(INDEX('Form Responses 1'!$D:$D,ROW()-4)="","",INDEX('Form Responses 1'!$T:$T,ROW()-4)),"")} | V7: =IF(B7="","",SUM(K7:N7)+IF(P7="Yes",2,0)) | W7: =IF(V7="","",IF(V7>=18,"HOT",IF(V7>=14,"WARM",IF(V7>=10,"WORK","NURTURE")))) | X7: =IF(B7="","",IF(OR(U7="Not a fit",U7="Follow later"),"Closed","Open")) | Y7: {=IFERROR(IF(INDEX('Form Responses 1'!$D:$D,ROW()-4)="","",INDEX('Form Responses 1'!$U:$U,ROW()-4)),"")}
A8: =IF(E8="","","LC-"&TEXT(ROW()-5,"000")) | B8: {=IFERROR(IF(INDEX('Form Responses 1'!$D:$D,ROW()-4)="","",INDEX('Form Responses 1'!$A:$A,ROW()-4)),"")} | C8: {=IFERROR(IF(INDEX('Form Responses 1'!$D:$D,ROW()-4)="","",INDEX('Form Responses 1'!$B:$B,ROW()-4)),"")} | D8: {=IFERROR(IF(INDEX('Form Responses 1'!$D:$D,ROW()-4)="","",INDEX('Form Responses 1'!$C:$C,ROW()-4)),"")} | E8: {=IFERROR(IF(INDEX('Form Responses 1'!$D:$D,ROW()-4)="","",INDEX('Form Responses 1'!$D:$D,ROW()-4)),"")} | F8: {=IFERROR(IF(INDEX('Form Responses 1'!$D:$D,ROW()-4)="","",INDEX('Form Responses 1'!$E:$E,ROW()-4)),"")} | G8: {=IFERROR(IF(INDEX('Form Responses 1'!$D:$D,ROW()-4)="","",INDEX('Form Responses 1'!$F:$F,ROW()-4)),"")} | H8: {=IFERROR(IF(INDEX('Form Responses 1'!$D:$D,ROW()-4)="","",INDEX('Form Responses 1'!$G:$G,ROW()-4)),"")} | I8: {=IFERROR(IF(INDEX('Form Responses 1'!$D:$D,ROW()-4)="","",INDEX('Form Responses 1'!$H:$H,ROW()-4)),"")} | J8: {=IFERROR(IF(INDEX('Form Responses 1'!$D:$D,ROW()-4)="","",INDEX('Form Responses 1'!$I:$I,ROW()-4)),"")} | K8: {=IFERROR(IF(INDEX('Form Responses 1'!$D:$D,ROW()-4)="","",INDEX('Form Responses 1'!$J:$J,ROW()-4)),"")} | L8: {=IFERROR(IF(INDEX('Form Responses 1'!$D:$D,ROW()-4)="","",INDEX('Form Responses 1'!$K:$K,ROW()-4)),"")} | M8: {=IFERROR(IF(INDEX('Form Responses 1'!$D:$D,ROW()-4)="","",INDEX('Form Responses 1'!$L:$L,ROW()-4)),"")} | N8: {=IFERROR(IF(INDEX('Form Responses 1'!$D:$D,ROW()-4)="","",INDEX('Form Responses 1'!$M:$M,ROW()-4)),"")} | O8: {=IFERROR(IF(INDEX('Form Responses 1'!$D:$D,ROW()-4)="","",INDEX('Form Responses 1'!$N:$N,ROW()-4)),"")} | P8: {=IFERROR(IF(INDEX('Form Responses 1'!$D:$D,ROW()-4)="","",INDEX('Form Responses 1'!$O:$O,ROW()-4)),"")} | Q8: {=IFERROR(IF(INDEX('Form Responses 1'!$D:$D,ROW()-4)="","",INDEX('Form Responses 1'!$P:$P,ROW()-4)),"")} | R8: {=IFERROR(IF(INDEX('Form Responses 1'!$D:$D,ROW()-4)="","",INDEX('Form Responses 1'!$Q:$Q,ROW()-4)),"")} | S8: {=IFERROR(IF(INDEX('Form Responses 1'!$D:$D,ROW()-4)="","",INDEX('Form Responses 1'!$R:$R,ROW()-4)),"")} | T8: {=IFERROR(IF(INDEX('Form Responses 1'!$D:$D,ROW()-4)="","",INDEX('Form Responses 1'!$S:$S,ROW()-4)),"")} | U8: {=IFERROR(IF(INDEX('Form Responses 1'!$D:$D,ROW()-4)="","",INDEX('Form Responses 1'!$T:$T,ROW()-4)),"")} | V8: =IF(B8="","",SUM(K8:N8)+IF(P8="Yes",2,0)) | W8: =IF(V8="","",IF(V8>=18,"HOT",IF(V8>=14,"WARM",IF(V8>=10,"WORK","NURTURE")))) | X8: =IF(B8="","",IF(OR(U8="Not a fit",U8="Follow later"),"Closed","Open")) | Y8: {=IFERROR(IF(INDEX('Form Responses 1'!$D:$D,ROW()-4)="","",INDEX('Form Responses 1'!$U:$U,ROW()-4)),"")}
A9: =IF(E9="","","LC-"&TEXT(ROW()-5,"000")) | B9: {=IFERROR(IF(INDEX('Form Responses 1'!$D:$D,ROW()-4)="","",INDEX('Form Responses 1'!$A:$A,ROW()-4)),"")} | C9: {=IFERROR(IF(INDEX('Form Responses 1'!$D:$D,ROW()-4)="","",INDEX('Form Responses 1'!$B:$B,ROW()-4)),"")} | D9: {=IFERROR(IF(INDEX('Form Responses 1'!$D:$D,ROW()-4)="","",INDEX('Form Responses 1'!$C:$C,ROW()-4)),"")} | E9: {=IFERROR(IF(INDEX('Form Responses 1'!$D:$D,ROW()-4)="","",INDEX('Form Responses 1'!$D:$D,ROW()-4)),"")} | F9: {=IFERROR(IF(INDEX('Form Responses 1'!$D:$D,ROW()-4)="","",INDEX('Form Responses 1'!$E:$E,ROW()-4)),"")} | G9: {=IFERROR(IF(INDEX('Form Responses 1'!$D:$D,ROW()-4)="","",INDEX('Form Responses 1'!$F:$F,ROW()-4)),"")} | H9: {=IFERROR(IF(INDEX('Form Responses 1'!$D:$D,ROW()-4)="","",INDEX('Form Responses 1'!$G:$G,ROW()-4)),"")} | I9: {=IFERROR(IF(INDEX('Form Responses 1'!$D:$D,ROW()-4)="","",INDEX('Form Responses 1'!$H:$H,ROW()-4)),"")} | J9: {=IFERROR(IF(INDEX('Form Responses 1'!$D:$D,ROW()-4)="","",INDEX('Form Responses 1'!$I:$I,ROW()-4)),"")} | K9: {=IFERROR(IF(INDEX('Form Responses 1'!$D:$D,ROW()-4)="","",INDEX('Form Responses 1'!$J:$J,ROW()-4)),"")} | L9: {=IFERROR(IF(INDEX('Form Responses 1'!$D:$D,ROW()-4)="","",INDEX('Form Responses 1'!$K:$K,ROW()-4)),"")} | M9: {=IFERROR(IF(INDEX('Form Responses 1'!$D:$D,ROW()-4)="","",INDEX('Form Responses 1'!$L:$L,ROW()-4)),"")} | N9: {=IFERROR(IF(INDEX('Form Responses 1'!$D:$D,ROW()-4)="","",INDEX('Form Responses 1'!$M:$M,ROW()-4)),"")} | O9: {=IFERROR(IF(INDEX('Form Responses 1'!$D:$D,ROW()-4)="","",INDEX('Form Responses 1'!$N:$N,ROW()-4)),"")} | P9: {=IFERROR(IF(INDEX('Form Responses 1'!$D:$D,ROW()-4)="","",INDEX('Form Responses 1'!$O:$O,ROW()-4)),"")} | Q9: {=IFERROR(IF(INDEX('Form Responses 1'!$D:$D,ROW()-4)="","",INDEX('Form Responses 1'!$P:$P,ROW()-4)),"")} | R9: {=IFERROR(IF(INDEX('Form Responses 1'!$D:$D,ROW()-4)="","",INDEX('Form Responses 1'!$Q:$Q,ROW()-4)),"")} | S9: {=IFERROR(IF(INDEX('Form Responses 1'!$D:$D,ROW()-4)="","",INDEX('Form Responses 1'!$R:$R,ROW()-4)),"")} | T9: {=IFERROR(IF(INDEX('Form Responses 1'!$D:$D,ROW()-4)="","",INDEX('Form Responses 1'!$S:$S,ROW()-4)),"")} | U9: {=IFERROR(IF(INDEX('Form Responses 1'!$D:$D,ROW()-4)="","",INDEX('Form Responses 1'!$T:$T,ROW()-4)),"")} | V9: =IF(B9="","",SUM(K9:N9)+IF(P9="Yes",2,0)) | W9: =IF(V9="","",IF(V9>=18,"HOT",IF(V9>=14,"WARM",IF(V9>=10,"WORK","NURTURE")))) | X9: =IF(B9="","",IF(OR(U9="Not a fit",U9="Follow later"),"Closed","Open")) | Y9: {=IFERROR(IF(INDEX('Form Responses 1'!$D:$D,ROW()-4)="","",INDEX('Form Responses 1'!$U:$U,ROW()-4)),"")}
A10: =IF(E10="","","LC-"&TEXT(ROW()-5,"000")) | B10: {=IFERROR(IF(INDEX('Form Responses 1'!$D:$D,ROW()-4)="","",INDEX('Form Responses 1'!$A:$A,ROW()-4)),"")} | C10: {=IFERROR(IF(INDEX('Form Responses 1'!$D:$D,ROW()-4)="","",INDEX('Form Responses 1'!$B:$B,ROW()-4)),"")} | D10: {=IFERROR(IF(INDEX('Form Responses 1'!$D:$D,ROW()-4)="","",INDEX('Form Responses 1'!$C:$C,ROW()-4)),"")} | E10: {=IFERROR(IF(INDEX('Form Responses 1'!$D:$D,ROW()-4)="","",INDEX('Form Responses 1'!$D:$D,ROW()-4)),"")} | F10: {=IFERROR(IF(INDEX('Form Responses 1'!$D:$D,ROW()-4)="","",INDEX('Form Responses 1'!$E:$E,ROW()-4)),"")} | G10: {=IFERROR(IF(INDEX('Form Responses 1'!$D:$D,ROW()-4)="","",INDEX('Form Responses 1'!$F:$F,ROW()-4)),"")} | H10: {=IFERROR(IF(INDEX('Form Responses 1'!$D:$D,ROW()-4)="","",INDEX('Form Responses 1'!$G:$G,ROW()-4)),"")} | I10: {=IFERROR(IF(INDEX('Form Responses 1'!$D:$D,ROW()-4)="","",INDEX('Form Responses 1'!$H:$H,ROW()-4)),"")} | J10: {=IFERROR(IF(INDEX('Form Responses 1'!$D:$D,ROW()-4)="","",INDEX('Form Responses 1'!$I:$I,ROW()-4)),"")} | K10: {=IFERROR(IF(INDEX('Form Responses 1'!$D:$D,ROW()-4)="","",INDEX('Form Responses 1'!$J:$J,ROW()-4)),"")} | L10: {=IFERROR(IF(INDEX('Form Responses 1'!$D:$D,ROW()-4)="","",INDEX('Form Responses 1'!$K:$K,ROW()-4)),"")} | M10: {=IFERROR(IF(INDEX('Form Responses 1'!$D:$D,ROW()-4)="","",INDEX('Form Responses 1'!$L:$L,ROW()-4)),"")} | N10: {=IFERROR(IF(INDEX('Form Responses 1'!$D:$D,ROW()-4)="","",INDEX('Form Responses 1'!$M:$M,ROW()-4)),"")} | O10: {=IFERROR(IF(INDEX('Form Responses 1'!$D:$D,ROW()-4)="","",INDEX('Form Responses 1'!$N:$N,ROW()-4)),"")} | P10: {=IFERROR(IF(INDEX('Form Responses 1'!$D:$D,ROW()-4)="","",INDEX('Form Responses 1'!$O:$O,ROW()-4)),"")} | Q10: {=IFERROR(IF(INDEX('Form Responses 1'!$D:$D,ROW()-4)="","",INDEX('Form Responses 1'!$P:$P,ROW()-4)),"")} | R10: {=IFERROR(IF(INDEX('Form Responses 1'!$D:$D,ROW()-4)="","",INDEX('Form Responses 1'!$Q:$Q,ROW()-4)),"")} | S10: {=IFERROR(IF(INDEX('Form Responses 1'!$D:$D,ROW()-4)="","",INDEX('Form Responses 1'!$R:$R,ROW()-4)),"")} | T10: {=IFERROR(IF(INDEX('Form Responses 1'!$D:$D,ROW()-4)="","",INDEX('Form Responses 1'!$S:$S,ROW()-4)),"")} | U10: {=IFERROR(IF(INDEX('Form Responses 1'!$D:$D,ROW()-4)="","",INDEX('Form Responses 1'!$T:$T,ROW()-4)),"")} | V10: =IF(B10="","",SUM(K10:N10)+IF(P10="Yes",2,0)) | W10: =IF(V10="","",IF(V10>=18,"HOT",IF(V10>=14,"WARM",IF(V10>=10,"WORK","NURTURE")))) | X10: =IF(B10="","",IF(OR(U10="Not a fit",U10="Follow later"),"Closed","Open")) | Y10: {=IFERROR(IF(INDEX('Form Responses 1'!$D:$D,ROW()-4)="","",INDEX('Form Responses 1'!$U:$U,ROW()-4)),"")}
A11: =IF(E11="","","LC-"&TEXT(ROW()-5,"000")) | B11: {=IFERROR(IF(INDEX('Form Responses 1'!$D:$D,ROW()-4)="","",INDEX('Form Responses 1'!$A:$A,ROW()-4)),"")} | C11: {=IFERROR(IF(INDEX('Form Responses 1'!$D:$D,ROW()-4)="","",INDEX('Form Responses 1'!$B:$B,ROW()-4)),"")} | D11: {=IFERROR(IF(INDEX('Form Responses 1'!$D:$D,ROW()-4)="","",INDEX('Form Responses 1'!$C:$C,ROW()-4)),"")} | E11: {=IFERROR(IF(INDEX('Form Responses 1'!$D:$D,ROW()-4)="","",INDEX('Form Responses 1'!$D:$D,ROW()-4)),"")} | F11: {=IFERROR(IF(INDEX('Form Responses 1'!$D:$D,ROW()-4)="","",INDEX('Form Responses 1'!$E:$E,ROW()-4)),"")} | G11: {=IFERROR(IF(INDEX('Form Responses 1'!$D:$D,ROW()-4)="","",INDEX('Form Responses 1'!$F:$F,ROW()-4)),"")} | H11: {=IFERROR(IF(INDEX('Form Responses 1'!$D:$D,ROW()-4)="","",INDEX('Form Responses 1'!$G:$G,ROW()-4)),"")} | I11: {=IFERROR(IF(INDEX('Form Responses 1'!$D:$D,ROW()-4)="","",INDEX('Form Responses 1'!$H:$H,ROW()-4)),"")} | J11: {=IFERROR(IF(INDEX('Form Responses 1'!$D:$D,ROW()-4)="","",INDEX('Form Responses 1'!$I:$I,ROW()-4)),"")} | K11: {=IFERROR(IF(INDEX('Form Responses 1'!$D:$D,ROW()-4)="","",INDEX('Form Responses 1'!$J:$J,ROW()-4)),"")} | L11: {=IFERROR(IF(INDEX('Form Responses 1'!$D:$D,ROW()-4)="","",INDEX('Form Responses 1'!$K:$K,ROW()-4)),"")} | M11: {=IFERROR(IF(INDEX('Form Responses 1'!$D:$D,ROW()-4)="","",INDEX('Form Responses 1'!$L:$L,ROW()-4)),"")} | N11: {=IFERROR(IF(INDEX('Form Responses 1'!$D:$D,ROW()-4)="","",INDEX('Form Responses 1'!$M:$M,ROW()-4)),"")} | O11: {=IFERROR(IF(INDEX('Form Responses 1'!$D:$D,ROW()-4)="","",INDEX('Form Responses 1'!$N:$N,ROW()-4)),"")} | P11: {=IFERROR(IF(INDEX('Form Responses 1'!$D:$D,ROW()-4)="","",INDEX('Form Responses 1'!$O:$O,ROW()-4)),"")} | Q11: {=IFERROR(IF(INDEX('Form Responses 1'!$D:$D,ROW()-4)="","",INDEX('Form Responses 1'!$P:$P,ROW()-4)),"")} | R11: {=IFERROR(IF(INDEX('Form Responses 1'!$D:$D,ROW()-4)="","",INDEX('Form Responses 1'!$Q:$Q,ROW()-4)),"")} | S11: {=IFERROR(IF(INDEX('Form Responses 1'!$D:$D,ROW()-4)="","",INDEX('Form Responses 1'!$R:$R,ROW()-4)),"")} | T11: {=IFERROR(IF(INDEX('Form Responses 1'!$D:$D,ROW()-4)="","",INDEX('Form Responses 1'!$S:$S,ROW()-4)),"")} | U11: {=IFERROR(IF(INDEX('Form Responses 1'!$D:$D,ROW()-4)="","",INDEX('Form Responses 1'!$T:$T,ROW()-4)),"")} | V11: =IF(B11="","",SUM(K11:N11)+IF(P11="Yes",2,0)) | W11: =IF(V11="","",IF(V11>=18,"HOT",IF(V11>=14,"WARM",IF(V11>=10,"WORK","NURTURE")))) | X11: =IF(B11="","",IF(OR(U11="Not a fit",U11="Follow later"),"Closed","Open")) | Y11: {=IFERROR(IF(INDEX('Form Responses 1'!$D:$D,ROW()-4)="","",INDEX('Form Responses 1'!$U:$U,ROW()-4)),"")}
A12: =IF(E12="","","LC-"&TEXT(ROW()-5,"000")) | B12: {=IFERROR(IF(INDEX('Form Responses 1'!$D:$D,ROW()-4)="","",INDEX('Form Responses 1'!$A:$A,ROW()-4)),"")} | C12: {=IFERROR(IF(INDEX('Form Responses 1'!$D:$D,ROW()-4)="","",INDEX('Form Responses 1'!$B:$B,ROW()-4)),"")} | D12: {=IFERROR(IF(INDEX('Form Responses 1'!$D:$D,ROW()-4)="","",INDEX('Form Responses 1'!$C:$C,ROW()-4)),"")} | E12: {=IFERROR(IF(INDEX('Form Responses 1'!$D:$D,ROW()-4)="","",INDEX('Form Responses 1'!$D:$D,ROW()-4)),"")} | F12: {=IFERROR(IF(INDEX('Form Responses 1'!$D:$D,ROW()-4)="","",INDEX('Form Responses 1'!$E:$E,ROW()-4)),"")} | G12: {=IFERROR(IF(INDEX('Form Responses 1'!$D:$D,ROW()-4)="","",INDEX('Form Responses 1'!$F:$F,ROW()-4)),"")} | H12: {=IFERROR(IF(INDEX('Form Responses 1'!$D:$D,ROW()-4)="","",INDEX('Form Responses 1'!$G:$G,ROW()-4)),"")} | I12: {=IFERROR(IF(INDEX('Form Responses 1'!$D:$D,ROW()-4)="","",INDEX('Form Responses 1'!$H:$H,ROW()-4)),"")} | J12: {=IFERROR(IF(INDEX('Form Responses 1'!$D:$D,ROW()-4)="","",INDEX('Form Responses 1'!$I:$I,ROW()-4)),"")} | K12: {=IFERROR(IF(INDEX('Form Responses 1'!$D:$D,ROW()-4)="","",INDEX('Form Responses 1'!$J:$J,ROW()-4)),"")} | L12: {=IFERROR(IF(INDEX('Form Responses 1'!$D:$D,ROW()-4)="","",INDEX('Form Responses 1'!$K:$K,ROW()-4)),"")} | M12: {=IFERROR(IF(INDEX('Form Responses 1'!$D:$D,ROW()-4)="","",INDEX('Form Responses 1'!$L:$L,ROW()-4)),"")} | N12: {=IFERROR(IF(INDEX('Form Responses 1'!$D:$D,ROW()-4)="","",INDEX('Form Responses 1'!$M:$M,ROW()-4)),"")} | O12: {=IFERROR(IF(INDEX('Form Responses 1'!$D:$D,ROW()-4)="","",INDEX('Form Responses 1'!$N:$N,ROW()-4)),"")} | P12: {=IFERROR(IF(INDEX('Form Responses 1'!$D:$D,ROW()-4)="","",INDEX('Form Responses 1'!$O:$O,ROW()-4)),"")} | Q12: {=IFERROR(IF(INDEX('Form Responses 1'!$D:$D,ROW()-4)="","",INDEX('Form Responses 1'!$P:$P,ROW()-4)),"")} | R12: {=IFERROR(IF(INDEX('Form Responses 1'!$D:$D,ROW()-4)="","",INDEX('Form Responses 1'!$Q:$Q,ROW()-4)),"")} | S12: {=IFERROR(IF(INDEX('Form Responses 1'!$D:$D,ROW()-4)="","",INDEX('Form Responses 1'!$R:$R,ROW()-4)),"")} | T12: {=IFERROR(IF(INDEX('Form Responses 1'!$D:$D,ROW()-4)="","",INDEX('Form Responses 1'!$S:$S,ROW()-4)),"")} | U12: {=IFERROR(IF(INDEX('Form Responses 1'!$D:$D,ROW()-4)="","",INDEX('Form Responses 1'!$T:$T,ROW()-4)),"")} | V12: =IF(B12="","",SUM(K12:N12)+IF(P12="Yes",2,0)) | W12: =IF(V12="","",IF(V12>=18,"HOT",IF(V12>=14,"WARM",IF(V12>=10,"WORK","NURTURE")))) | X12: =IF(B12="","",IF(OR(U12="Not a fit",U12="Follow later"),"Closed","Open")) | Y12: {=IFERROR(IF(INDEX('Form Responses 1'!$D:$D,ROW()-4)="","",INDEX('Form Responses 1'!$U:$U,ROW()-4)),"")}
A13: =IF(E13="","","LC-"&TEXT(ROW()-5,"000")) | B13: {=IFERROR(IF(INDEX('Form Responses 1'!$D:$D,ROW()-4)="","",INDEX('Form Responses 1'!$A:$A,ROW()-4)),"")} | C13: {=IFERROR(IF(INDEX('Form Responses 1'!$D:$D,ROW()-4)="","",INDEX('Form Responses 1'!$B:$B,ROW()-4)),"")} | D13: {=IFERROR(IF(INDEX('Form Responses 1'!$D:$D,ROW()-4)="","",INDEX('Form Responses 1'!$C:$C,ROW()-4)),"")} | E13: {=IFERROR(IF(INDEX('Form Responses 1'!$D:$D,ROW()-4)="","",INDEX('Form Responses 1'!$D:$D,ROW()-4)),"")} | F13: {=IFERROR(IF(INDEX('Form Responses 1'!$D:$D,ROW()-4)="","",INDEX('Form Responses 1'!$E:$E,ROW()-4)),"")} | G13: {=IFERROR(IF(INDEX('Form Responses 1'!$D:$D,ROW()-4)="","",INDEX('Form Responses 1'!$F:$F,ROW()-4)),"")} | H13: {=IFERROR(IF(INDEX('Form Responses 1'!$D:$D,ROW()-4)="","",INDEX('Form Responses 1'!$G:$G,ROW()-4)),"")} | I13: {=IFERROR(IF(INDEX('Form Responses 1'!$D:$D,ROW()-4)="","",INDEX('Form Responses 1'!$H:$H,ROW()-4)),"")} | J13: {=IFERROR(IF(INDEX('Form Responses 1'!$D:$D,ROW()-4)="","",INDEX('Form Responses 1'!$I:$I,ROW()-4)),"")} | K13: {=IFERROR(IF(INDEX('Form Responses 1'!$D:$D,ROW()-4)="","",INDEX('Form Responses 1'!$J:$J,ROW()-4)),"")} | L13: {=IFERROR(IF(INDEX('Form Responses 1'!$D:$D,ROW()-4)="","",INDEX('Form Responses 1'!$K:$K,ROW()-4)),"")} | M13: {=IFERROR(IF(INDEX('Form Responses 1'!$D:$D,ROW()-4)="","",INDEX('Form Responses 1'!$L:$L,ROW()-4)),"")} | N13: {=IFERROR(IF(INDEX('Form Responses 1'!$D:$D,ROW()-4)="","",INDEX('Form Responses 1'!$M:$M,ROW()-4)),"")} | O13: {=IFERROR(IF(INDEX('Form Responses 1'!$D:$D,ROW()-4)="","",INDEX('Form Responses 1'!$N:$N,ROW()-4)),"")} | P13: {=IFERROR(IF(INDEX('Form Responses 1'!$D:$D,ROW()-4)="","",INDEX('Form Responses 1'!$O:$O,ROW()-4)),"")} | Q13: {=IFERROR(IF(INDEX('Form Responses 1'!$D:$D,ROW()-4)="","",INDEX('Form Responses 1'!$P:$P,ROW()-4)),"")} | R13: {=IFERROR(IF(INDEX('Form Responses 1'!$D:$D,ROW()-4)="","",INDEX('Form Responses 1'!$Q:$Q,ROW()-4)),"")} | S13: {=IFERROR(IF(INDEX('Form Responses 1'!$D:$D,ROW()-4)="","",INDEX('Form Responses 1'!$R:$R,ROW()-4)),"")} | T13: {=IFERROR(IF(INDEX('Form Responses 1'!$D:$D,ROW()-4)="","",INDEX('Form Responses 1'!$S:$S,ROW()-4)),"")} | U13: {=IFERROR(IF(INDEX('Form Responses 1'!$D:$D,ROW()-4)="","",INDEX('Form Responses 1'!$T:$T,ROW()-4)),"")} | V13: =IF(B13="","",SUM(K13:N13)+IF(P13="Yes",2,0)) | W13: =IF(V13="","",IF(V13>=18,"HOT",IF(V13>=14,"WARM",IF(V13>=10,"WORK","NURTURE")))) | X13: =IF(B13="","",IF(OR(U13="Not a fit",U13="Follow later"),"Closed","Open")) | Y13: {=IFERROR(IF(INDEX('Form Responses 1'!$D:$D,ROW()-4)="","",INDEX('Form Responses 1'!$U:$U,ROW()-4)),"")}
A14: =IF(E14="","","LC-"&TEXT(ROW()-5,"000")) | B14: {=IFERROR(IF(INDEX('Form Responses 1'!$D:$D,ROW()-4)="","",INDEX('Form Responses 1'!$A:$A,ROW()-4)),"")} | C14: {=IFERROR(IF(INDEX('Form Responses 1'!$D:$D,ROW()-4)="","",INDEX('Form Responses 1'!$B:$B,ROW()-4)),"")} | D14: {=IFERROR(IF(INDEX('Form Responses 1'!$D:$D,ROW()-4)="","",INDEX('Form Responses 1'!$C:$C,ROW()-4)),"")} | E14: {=IFERROR(IF(INDEX('Form Responses 1'!$D:$D,ROW()-4)="","",INDEX('Form Responses 1'!$D:$D,ROW()-4)),"")} | F14: {=IFERROR(IF(INDEX('Form Responses 1'!$D:$D,ROW()-4)="","",INDEX('Form Responses 1'!$E:$E,ROW()-4)),"")} | G14: {=IFERROR(IF(INDEX('Form Responses 1'!$D:$D,ROW()-4)="","",INDEX('Form Responses 1'!$F:$F,ROW()-4)),"")} | H14: {=IFERROR(IF(INDEX('Form Responses 1'!$D:$D,ROW()-4)="","",INDEX('Form Responses 1'!$G:$G,ROW()-4)),"")} | I14: {=IFERROR(IF(INDEX('Form Responses 1'!$D:$D,ROW()-4)="","",INDEX('Form Responses 1'!$H:$H,ROW()-4)),"")} | J14: {=IFERROR(IF(INDEX('Form Responses 1'!$D:$D,ROW()-4)="","",INDEX('Form Responses 1'!$I:$I,ROW()-4)),"")} | K14: {=IFERROR(IF(INDEX('Form Responses 1'!$D:$D,ROW()-4)="","",INDEX('Form Responses 1'!$J:$J,ROW()-4)),"")} | L14: {=IFERROR(IF(INDEX('Form Responses 1'!$D:$D,ROW()-4)="","",INDEX('Form Responses 1'!$K:$K,ROW()-4)),"")} | M14: {=IFERROR(IF(INDEX('Form Responses 1'!$D:$D,ROW()-4)="","",INDEX('Form Responses 1'!$L:$L,ROW()-4)),"")} | N14: {=IFERROR(IF(INDEX('Form Responses 1'!$D:$D,ROW()-4)="","",INDEX('Form Responses 1'!$M:$M,ROW()-4)),"")} | O14: {=IFERROR(IF(INDEX('Form Responses 1'!$D:$D,ROW()-4)="","",INDEX('Form Responses 1'!$N:$N,ROW()-4)),"")} | P14: {=IFERROR(IF(INDEX('Form Responses 1'!$D:$D,ROW()-4)="","",INDEX('Form Responses 1'!$O:$O,ROW()-4)),"")} | Q14: {=IFERROR(IF(INDEX('Form Responses 1'!$D:$D,ROW()-4)="","",INDEX('Form Responses 1'!$P:$P,ROW()-4)),"")} | R14: {=IFERROR(IF(INDEX('Form Responses 1'!$D:$D,ROW()-4)="","",INDEX('Form Responses 1'!$Q:$Q,ROW()-4)),"")} | S14: {=IFERROR(IF(INDEX('Form Responses 1'!$D:$D,ROW()-4)="","",INDEX('Form Responses 1'!$R:$R,ROW()-4)),"")} | T14: {=IFERROR(IF(INDEX('Form Responses 1'!$D:$D,ROW()-4)="","",INDEX('Form Responses 1'!$S:$S,ROW()-4)),"")} | U14: {=IFERROR(IF(INDEX('Form Responses 1'!$D:$D,ROW()-4)="","",INDEX('Form Responses 1'!$T:$T,ROW()-4)),"")} | V14: =IF(B14="","",SUM(K14:N14)+IF(P14="Yes",2,0)) | W14: =IF(V14="","",IF(V14>=18,"HOT",IF(V14>=14,"WARM",IF(V14>=10,"WORK","NURTURE")))) | X14: =IF(B14="","",IF(OR(U14="Not a fit",U14="Follow later"),"Closed","Open")) | Y14: {=IFERROR(IF(INDEX('Form Responses 1'!$D:$D,ROW()-4)="","",INDEX('Form Responses 1'!$U:$U,ROW()-4)),"")}
A15: =IF(E15="","","LC-"&TEXT(ROW()-5,"000")) | B15: {=IFERROR(IF(INDEX('Form Responses 1'!$D:$D,ROW()-4)="","",INDEX('Form Responses 1'!$A:$A,ROW()-4)),"")} | C15: {=IFERROR(IF(INDEX('Form Responses 1'!$D:$D,ROW()-4)="","",INDEX('Form Responses 1'!$B:$B,ROW()-4)),"")} | D15: {=IFERROR(IF(INDEX('Form Responses 1'!$D:$D,ROW()-4)="","",INDEX('Form Responses 1'!$C:$C,ROW()-4)),"")} | E15: {=IFERROR(IF(INDEX('Form Responses 1'!$D:$D,ROW()-4)="","",INDEX('Form Responses 1'!$D:$D,ROW()-4)),"")} | F15: {=IFERROR(IF(INDEX('Form Responses 1'!$D:$D,ROW()-4)="","",INDEX('Form Responses 1'!$E:$E,ROW()-4)),"")} | G15: {=IFERROR(IF(INDEX('Form Responses 1'!$D:$D,ROW()-4)="","",INDEX('Form Responses 1'!$F:$F,ROW()-4)),"")} | H15: {=IFERROR(IF(INDEX('Form Responses 1'!$D:$D,ROW()-4)="","",INDEX('Form Responses 1'!$G:$G,ROW()-4)),"")} | I15: {=IFERROR(IF(INDEX('Form Responses 1'!$D:$D,ROW()-4)="","",INDEX('Form Responses 1'!$H:$H,ROW()-4)),"")} | J15: {=IFERROR(IF(INDEX('Form Responses 1'!$D:$D,ROW()-4)="","",INDEX('Form Responses 1'!$I:$I,ROW()-4)),"")} | K15: {=IFERROR(IF(INDEX('Form Responses 1'!$D:$D,ROW()-4)="","",INDEX('Form Responses 1'!$J:$J,ROW()-4)),"")} | L15: {=IFERROR(IF(INDEX('Form Responses 1'!$D:$D,ROW()-4)="","",INDEX('Form Responses 1'!$K:$K,ROW()-4)),"")} | M15: {=IFERROR(IF(INDEX('Form Responses 1'!$D:$D,ROW()-4)="","",INDEX('Form Responses 1'!$L:$L,ROW()-4)),"")} | N15: {=IFERROR(IF(INDEX('Form Responses 1'!$D:$D,ROW()-4)="","",INDEX('Form Responses 1'!$M:$M,ROW()-4)),"")} | O15: {=IFERROR(IF(INDEX('Form Responses 1'!$D:$D,ROW()-4)="","",INDEX('Form Responses 1'!$N:$N,ROW()-4)),"")} | P15: {=IFERROR(IF(INDEX('Form Responses 1'!$D:$D,ROW()-4)="","",INDEX('Form Responses 1'!$O:$O,ROW()-4)),"")} | Q15: {=IFERROR(IF(INDEX('Form Responses 1'!$D:$D,ROW()-4)="","",INDEX('Form Responses 1'!$P:$P,ROW()-4)),"")} | R15: {=IFERROR(IF(INDEX('Form Responses 1'!$D:$D,ROW()-4)="","",INDEX('Form Responses 1'!$Q:$Q,ROW()-4)),"")} | S15: {=IFERROR(IF(INDEX('Form Responses 1'!$D:$D,ROW()-4)="","",INDEX('Form Responses 1'!$R:$R,ROW()-4)),"")} | T15: {=IFERROR(IF(INDEX('Form Responses 1'!$D:$D,ROW()-4)="","",INDEX('Form Responses 1'!$S:$S,ROW()-4)),"")} | U15: {=IFERROR(IF(INDEX('Form Responses 1'!$D:$D,ROW()-4)="","",INDEX('Form Responses 1'!$T:$T,ROW()-4)),"")} | V15: =IF(B15="","",SUM(K15:N15)+IF(P15="Yes",2,0)) | W15: =IF(V15="","",IF(V15>=18,"HOT",IF(V15>=14,"WARM",IF(V15>=10,"WORK","NURTURE")))) | X15: =IF(B15="","",IF(OR(U15="Not a fit",U15="Follow later"),"Closed","Open")) | Y15: {=IFERROR(IF(INDEX('Form Responses 1'!$D:$D,ROW()-4)="","",INDEX('Form Responses 1'!$U:$U,ROW()-4)),"")}
A16: =IF(E16="","","LC-"&TEXT(ROW()-5,"000")) | B16: {=IFERROR(IF(INDEX('Form Responses 1'!$D:$D,ROW()-4)="","",INDEX('Form Responses 1'!$A:$A,ROW()-4)),"")} | C16: {=IFERROR(IF(INDEX('Form Responses 1'!$D:$D,ROW()-4)="","",INDEX('Form Responses 1'!$B:$B,ROW()-4)),"")} | D16: {=IFERROR(IF(INDEX('Form Responses 1'!$D:$D,ROW()-4)="","",INDEX('Form Responses 1'!$C:$C,ROW()-4)),"")} | E16: {=IFERROR(IF(INDEX('Form Responses 1'!$D:$D,ROW()-4)="","",INDEX('Form Responses 1'!$D:$D,ROW()-4)),"")} | F16: {=IFERROR(IF(INDEX('Form Responses 1'!$D:$D,ROW()-4)="","",INDEX('Form Responses 1'!$E:$E,ROW()-4)),"")} | G16: {=IFERROR(IF(INDEX('Form Responses 1'!$D:$D,ROW()-4)="","",INDEX('Form Responses 1'!$F:$F,ROW()-4)),"")} | H16: {=IFERROR(IF(INDEX('Form Responses 1'!$D:$D,ROW()-4)="","",INDEX('Form Responses 1'!$G:$G,ROW()-4)),"")} | I16: {=IFERROR(IF(INDEX('Form Responses 1'!$D:$D,ROW()-4)="","",INDEX('Form Responses 1'!$H:$H,ROW()-4)),"")} | J16: {=IFERROR(IF(INDEX('Form Responses 1'!$D:$D,ROW()-4)="","",INDEX('Form Responses 1'!$I:$I,ROW()-4)),"")} | K16: {=IFERROR(IF(INDEX('Form Responses 1'!$D:$D,ROW()-4)="","",INDEX('Form Responses 1'!$J:$J,ROW()-4)),"")} | L16: {=IFERROR(IF(INDEX('Form Responses 1'!$D:$D,ROW()-4)="","",INDEX('Form Responses 1'!$K:$K,ROW()-4)),"")} | M16: {=IFERROR(IF(INDEX('Form Responses 1'!$D:$D,ROW()-4)="","",INDEX('Form Responses 1'!$L:$L,ROW()-4)),"")} | N16: {=IFERROR(IF(INDEX('Form Responses 1'!$D:$D,ROW()-4)="","",INDEX('Form Responses 1'!$M:$M,ROW()-4)),"")} | O16: {=IFERROR(IF(INDEX('Form Responses 1'!$D:$D,ROW()-4)="","",INDEX('Form Responses 1'!$N:$N,ROW()-4)),"")} | P16: {=IFERROR(IF(INDEX('Form Responses 1'!$D:$D,ROW()-4)="","",INDEX('Form Responses 1'!$O:$O,ROW()-4)),"")} | Q16: {=IFERROR(IF(INDEX('Form Responses 1'!$D:$D,ROW()-4)="","",INDEX('Form Responses 1'!$P:$P,ROW()-4)),"")} | R16: {=IFERROR(IF(INDEX('Form Responses 1'!$D:$D,ROW()-4)="","",INDEX('Form Responses 1'!$Q:$Q,ROW()-4)),"")} | S16: {=IFERROR(IF(INDEX('Form Responses 1'!$D:$D,ROW()-4)="","",INDEX('Form Responses 1'!$R:$R,ROW()-4)),"")} | T16: {=IFERROR(IF(INDEX('Form Responses 1'!$D:$D,ROW()-4)="","",INDEX('Form Responses 1'!$S:$S,ROW()-4)),"")} | U16: {=IFERROR(IF(INDEX('Form Responses 1'!$D:$D,ROW()-4)="","",INDEX('Form Responses 1'!$T:$T,ROW()-4)),"")} | V16: =IF(B16="","",SUM(K16:N16)+IF(P16="Yes",2,0)) | W16: =IF(V16="","",IF(V16>=18,"HOT",IF(V16>=14,"WARM",IF(V16>=10,"WORK","NURTURE")))) | X16: =IF(B16="","",IF(OR(U16="Not a fit",U16="Follow later"),"Closed","Open")) | Y16: {=IFERROR(IF(INDEX('Form Responses 1'!$D:$D,ROW()-4)="","",INDEX('Form Responses 1'!$U:$U,ROW()-4)),"")}
A17: =IF(E17="","","LC-"&TEXT(ROW()-5,"000")) | B17: {=IFERROR(IF(INDEX('Form Responses 1'!$D:$D,ROW()-4)="","",INDEX('Form Responses 1'!$A:$A,ROW()-4)),"")} | C17: {=IFERROR(IF(INDEX('Form Responses 1'!$D:$D,ROW()-4)="","",INDEX('Form Responses 1'!$B:$B,ROW()-4)),"")} | D17: {=IFERROR(IF(INDEX('Form Responses 1'!$D:$D,ROW()-4)="","",INDEX('Form Responses 1'!$C:$C,ROW()-4)),"")} | E17: {=IFERROR(IF(INDEX('Form Responses 1'!$D:$D,ROW()-4)="","",INDEX('Form Responses 1'!$D:$D,ROW()-4)),"")} | F17: {=IFERROR(IF(INDEX('Form Responses 1'!$D:$D,ROW()-4)="","",INDEX('Form Responses 1'!$E:$E,ROW()-4)),"")} | G17: {=IFERROR(IF(INDEX('Form Responses 1'!$D:$D,ROW()-4)="","",INDEX('Form Responses 1'!$F:$F,ROW()-4)),"")} | H17: {=IFERROR(IF(INDEX('Form Responses 1'!$D:$D,ROW()-4)="","",INDEX('Form Responses 1'!$G:$G,ROW()-4)),"")} | I17: {=IFERROR(IF(INDEX('Form Responses 1'!$D:$D,ROW()-4)="","",INDEX('Form Responses 1'!$H:$H,ROW()-4)),"")} | J17: {=IFERROR(IF(INDEX('Form Responses 1'!$D:$D,ROW()-4)="","",INDEX('Form Responses 1'!$I:$I,ROW()-4)),"")} | K17: {=IFERROR(IF(INDEX('Form Responses 1'!$D:$D,ROW()-4)="","",INDEX('Form Responses 1'!$J:$J,ROW()-4)),"")} | L17: {=IFERROR(IF(INDEX('Form Responses 1'!$D:$D,ROW()-4)="","",INDEX('Form Responses 1'!$K:$K,ROW()-4)),"")} | M17: {=IFERROR(IF(INDEX('Form Responses 1'!$D:$D,ROW()-4)="","",INDEX('Form Responses 1'!$L:$L,ROW()-4)),"")} | N17: {=IFERROR(IF(INDEX('Form Responses 1'!$D:$D,ROW()-4)="","",INDEX('Form Responses 1'!$M:$M,ROW()-4)),"")} | O17: {=IFERROR(IF(INDEX('Form Responses 1'!$D:$D,ROW()-4)="","",INDEX('Form Responses 1'!$N:$N,ROW()-4)),"")} | P17: {=IFERROR(IF(INDEX('Form Responses 1'!$D:$D,ROW()-4)="","",INDEX('Form Responses 1'!$O:$O,ROW()-4)),"")} | Q17: {=IFERROR(IF(INDEX('Form Responses 1'!$D:$D,ROW()-4)="","",INDEX('Form Responses 1'!$P:$P,ROW()-4)),"")} | R17: {=IFERROR(IF(INDEX('Form Responses 1'!$D:$D,ROW()-4)="","",INDEX('Form Responses 1'!$Q:$Q,ROW()-4)),"")} | S17: {=IFERROR(IF(INDEX('Form Responses 1'!$D:$D,ROW()-4)="","",INDEX('Form Responses 1'!$R:$R,ROW()-4)),"")} | T17: {=IFERROR(IF(INDEX('Form Responses 1'!$D:$D,ROW()-4)="","",INDEX('Form Responses 1'!$S:$S,ROW()-4)),"")} | U17: {=IFERROR(IF(INDEX('Form Responses 1'!$D:$D,ROW()-4)="","",INDEX('Form Responses 1'!$T:$T,ROW()-4)),"")} | V17: =IF(B17="","",SUM(K17:N17)+IF(P17="Yes",2,0)) | W17: =IF(V17="","",IF(V17>=18,"HOT",IF(V17>=14,"WARM",IF(V17>=10,"WORK","NURTURE")))) | X17: =IF(B17="","",IF(OR(U17="Not a fit",U17="Follow later"),"Closed","Open")) | Y17: {=IFERROR(IF(INDEX('Form Responses 1'!$D:$D,ROW()-4)="","",INDEX('Form Responses 1'!$U:$U,ROW()-4)),"")}
... A505: =IF(E505="","","LC-"&TEXT(ROW()-5,"000")) | B505: {=IFERROR(IF(INDEX('Form Responses 1'!$D:$D,ROW()-4)="","",INDEX('Form Responses 1'!$A:$A,ROW()-4)),"")} | C505: {=IFERROR(IF(INDEX('Form Responses 1'!$D:$D,ROW()-4)="","",INDEX('Form Responses 1'!$B:$B,ROW()-4)),"")} | D505: {=IFERROR(IF(INDEX('Form Responses 1'!$D:$D,ROW()-4)="","",INDEX('Form Responses 1'!$C:$C,ROW()-4)),"")} | E505: {=IFERROR(IF(INDEX('Form Responses 1'!$D:$D,ROW()-4)="","",INDEX('Form Responses 1'!$D:$D,ROW()-4)),"")} | F505: {=IFERROR(IF(INDEX('Form Responses 1'!$D:$D,ROW()-4)="","",INDEX('Form Responses 1'!$E:$E,ROW()-4)),"")} | G505: {=IFERROR(IF(INDEX('Form Responses 1'!$D:$D,ROW()-4)="","",INDEX('Form Responses 1'!$F:$F,ROW()-4)),"")} | H505: {=IFERROR(IF(INDEX('Form Responses 1'!$D:$D,ROW()-4)="","",INDEX('Form Responses 1'!$G:$G,ROW()-4)),"")} | I505: {=IFERROR(IF(INDEX('Form Responses 1'!$D:$D,ROW()-4)="","",INDEX('Form Responses 1'!$H:$H,ROW()-4)),"")} | J505: {=IFERROR(IF(INDEX('Form Responses 1'!$D:$D,ROW()-4)="","",INDEX('Form Responses 1'!$I:$I,ROW()-4)),"")} | K505: {=IFERROR(IF(INDEX('Form Responses 1'!$D:$D,ROW()-4)="","",INDEX('Form Responses 1'!$J:$J,ROW()-4)),"")} | L505: {=IFERROR(IF(INDEX('Form Responses 1'!$D:$D,ROW()-4)="","",INDEX('Form Responses 1'!$K:$K,ROW()-4)),"")} | M505: {=IFERROR(IF(INDEX('Form Responses 1'!$D:$D,ROW()-4)="","",INDEX('Form Responses 1'!$L:$L,ROW()-4)),"")} | N505: {=IFERROR(IF(INDEX('Form Responses 1'!$D:$D,ROW()-4)="","",INDEX('Form Responses 1'!$M:$M,ROW()-4)),"")} | O505: {=IFERROR(IF(INDEX('Form Responses 1'!$D:$D,ROW()-4)="","",INDEX('Form Responses 1'!$N:$N,ROW()-4)),"")} | P505: {=IFERROR(IF(INDEX('Form Responses 1'!$D:$D,ROW()-4)="","",INDEX('Form Responses 1'!$O:$O,ROW()-4)),"")} | Q505: {=IFERROR(IF(INDEX('Form Responses 1'!$D:$D,ROW()-4)="","",INDEX('Form Responses 1'!$P:$P,ROW()-4)),"")} | R505: {=IFERROR(IF(INDEX('Form Responses 1'!$D:$D,ROW()-4)="","",INDEX('Form Responses 1'!$Q:$Q,ROW()-4)),"")} | S505: {=IFERROR(IF(INDEX('Form Responses 1'!$D:$D,ROW()-4)="","",INDEX('Form Responses 1'!$R:$R,ROW()-4)),"")} | T505: {=IFERROR(IF(INDEX('Form Responses 1'!$D:$D,ROW()-4)="","",INDEX('Form Responses 1'!$S:$S,ROW()-4)),"")} | U505: {=IFERROR(IF(INDEX('Form Responses 1'!$D:$D,ROW()-4)="","",INDEX('Form Responses 1'!$T:$T,ROW()-4)),"")} | V505: =IF(B505="","",SUM(K505:N505)+IF(P505="Yes",2,0)) | W505: =IF(V505="","",IF(V505>=18,"HOT",IF(V505>=14,"WARM",IF(V505>=10,"WORK","NURTURE")))) | X505: =IF(B505="","",IF(OR(U505="Not a fit",U505="Follow later"),"Closed","Open")) | Y505: {=IFERROR(IF(INDEX('Form Responses 1'!$D:$D,ROW()-4)="","",INDEX('Form Responses 1'!$U:$U,ROW()-4)),"")}

Sheet Mobile Capture Lite
A1: Timestamp | B1: Account | C1: Persona Name | D1: Meeting Type | E1: Requested Asset | F1: Need Primo | G1: Owner | H1: Due Date | I1: Notes
A2: Phone-friendly scratchpad for the show floor. Enter quick notes here if opening the full Live Capture tab feels like trying to parallel park a boat.
A4: Timestamp | B4: Account | C4: Persona | D4: Meeting Type | E4: Requested Asset | F4: Need Primo? | G4: Owner | H4: Due Date | I4: Band | J4: Notes
A5: =IF('Live Capture'!B6="","",'Live Capture'!B6) -> 46106.495 | B5: =IF('Live Capture'!B6="","",'Live Capture'!E6) -> Danone | C5: =IF('Live Capture'!B6="","",'Live Capture'!F6) -> Test Contact | D5: =IF('Live Capture'!B6="","",'Live Capture'!I6) -> Discovery | E5: =IF('Live Capture'!B6="","",'Live Capture'!O6) -> Infographic | F5: =IF('Live Capture'!B6="","",'Live Capture'!P6) -> Yes | G5: =IF('Live Capture'!B6="","",'Live Capture'!R6) -> Jake | H5: =IF('Live Capture'!B6="","",'Live Capture'!S6) -> 46107 | I5: =IF('Live Capture'!B6="","",'Live Capture'!W6) -> HOT | J5: =IF('Live Capture'!B6="","",'Live Capture'!Y6) -> Test submission from setup validation
A6: =IF('Live Capture'!B7="","",'Live Capture'!B7) | B6: =IF('Live Capture'!B7="","",'Live Capture'!E7) | C6: =IF('Live Capture'!B7="","",'Live Capture'!F7) | D6: =IF('Live Capture'!B7="","",'Live Capture'!I7) | E6: =IF('Live Capture'!B7="","",'Live Capture'!O7) | F6: =IF('Live Capture'!B7="","",'Live Capture'!P7) | G6: =IF('Live Capture'!B7="","",'Live Capture'!R7) | H6: =IF('Live Capture'!B7="","",'Live Capture'!S7) | I6: =IF('Live Capture'!B7="","",'Live Capture'!W7) | J6: =IF('Live Capture'!B7="","",'Live Capture'!Y7)
A7: =IF('Live Capture'!B8="","",'Live Capture'!B8) | B7: =IF('Live Capture'!B8="","",'Live Capture'!E8) | C7: =IF('Live Capture'!B8="","",'Live Capture'!F8) | D7: =IF('Live Capture'!B8="","",'Live Capture'!I8) | E7: =IF('Live Capture'!B8="","",'Live Capture'!O8) | F7: =IF('Live Capture'!B8="","",'Live Capture'!P8) | G7: =IF('Live Capture'!B8="","",'Live Capture'!R8) | H7: =IF('Live Capture'!B8="","",'Live Capture'!S8) | I7: =IF('Live Capture'!B8="","",'Live Capture'!W8) | J7: =IF('Live Capture'!B8="","",'Live Capture'!Y8)
A8: =IF('Live Capture'!B9="","",'Live Capture'!B9) | B8: =IF('Live Capture'!B9="","",'Live Capture'!E9) | C8: =IF('Live Capture'!B9="","",'Live Capture'!F9) | D8: =IF('Live Capture'!B9="","",'Live Capture'!I9) | E8: =IF('Live Capture'!B9="","",'Live Capture'!O9) | F8: =IF('Live Capture'!B9="","",'Live Capture'!P9) | G8: =IF('Live Capture'!B9="","",'Live Capture'!R9) | H8: =IF('Live Capture'!B9="","",'Live Capture'!S9) | I8: =IF('Live Capture'!B9="","",'Live Capture'!W9) | J8: =IF('Live Capture'!B9="","",'Live Capture'!Y9)
A9: =IF('Live Capture'!B10="","",'Live Capture'!B10) | B9: =IF('Live Capture'!B10="","",'Live Capture'!E10) | C9: =IF('Live Capture'!B10="","",'Live Capture'!F10) | D9: =IF('Live Capture'!B10="","",'Live Capture'!I10) | E9: =IF('Live Capture'!B10="","",'Live Capture'!O10) | F9: =IF('Live Capture'!B10="","",'Live Capture'!P10) | G9: =IF('Live Capture'!B10="","",'Live Capture'!R10) | H9: =IF('Live Capture'!B10="","",'Live Capture'!S10) | I9: =IF('Live Capture'!B10="","",'Live Capture'!W10) | J9: =IF('Live Capture'!B10="","",'Live Capture'!Y10)
A10: =IF('Live Capture'!B11="","",'Live Capture'!B11) | B10: =IF('Live Capture'!B11="","",'Live Capture'!E11) | C10: =IF('Live Capture'!B11="","",'Live Capture'!F11) | D10: =IF('Live Capture'!B11="","",'Live Capture'!I11) | E10: =IF('Live Capture'!B11="","",'Live Capture'!O11) | F10: =IF('Live Capture'!B11="","",'Live Capture'!P11) | G10: =IF('Live Capture'!B11="","",'Live Capture'!R11) | H10: =IF('Live Capture'!B11="","",'Live Capture'!S11) | I10: =IF('Live Capture'!B11="","",'Live Capture'!W11) | J10: =IF('Live Capture'!B11="","",'Live Capture'!Y11)
A11: =IF('Live Capture'!B12="","",'Live Capture'!B12) | B11: =IF('Live Capture'!B12="","",'Live Capture'!E12) | C11: =IF('Live Capture'!B12="","",'Live Capture'!F12) | D11: =IF('Live Capture'!B12="","",'Live Capture'!I12) | E11: =IF('Live Capture'!B12="","",'Live Capture'!O12) | F11: =IF('Live Capture'!B12="","",'Live Capture'!P12) | G11: =IF('Live Capture'!B12="","",'Live Capture'!R12) | H11: =IF('Live Capture'!B12="","",'Live Capture'!S12) | I11: =IF('Live Capture'!B12="","",'Live Capture'!W12) | J11: =IF('Live Capture'!B12="","",'Live Capture'!Y12)
A12: =IF('Live Capture'!B13="","",'Live Capture'!B13) | B12: =IF('Live Capture'!B13="","",'Live Capture'!E13) | C12: =IF('Live Capture'!B13="","",'Live Capture'!F13) | D12: =IF('Live Capture'!B13="","",'Live Capture'!I13) | E12: =IF('Live Capture'!B13="","",'Live Capture'!O13) | F12: =IF('Live Capture'!B13="","",'Live Capture'!P13) | G12: =IF('Live Capture'!B13="","",'Live Capture'!R13) | H12: =IF('Live Capture'!B13="","",'Live Capture'!S13) | I12: =IF('Live Capture'!B13="","",'Live Capture'!W13) | J12: =IF('Live Capture'!B13="","",'Live Capture'!Y13)
A13: =IF('Live Capture'!B14="","",'Live Capture'!B14) | B13: =IF('Live Capture'!B14="","",'Live Capture'!E14) | C13: =IF('Live Capture'!B14="","",'Live Capture'!F14) | D13: =IF('Live Capture'!B14="","",'Live Capture'!I14) | E13: =IF('Live Capture'!B14="","",'Live Capture'!O14) | F13: =IF('Live Capture'!B14="","",'Live Capture'!P14) | G13: =IF('Live Capture'!B14="","",'Live Capture'!R14) | H13: =IF('Live Capture'!B14="","",'Live Capture'!S14) | I13: =IF('Live Capture'!B14="","",'Live Capture'!W14) | J13: =IF('Live Capture'!B14="","",'Live Capture'!Y14)
A14: =IF('Live Capture'!B15="","",'Live Capture'!B15) | B14: =IF('Live Capture'!B15="","",'Live Capture'!E15) | C14: =IF('Live Capture'!B15="","",'Live Capture'!F15) | D14: =IF('Live Capture'!B15="","",'Live Capture'!I15) | E14: =IF('Live Capture'!B15="","",'Live Capture'!O15) | F14: =IF('Live Capture'!B15="","",'Live Capture'!P15) | G14: =IF('Live Capture'!B15="","",'Live Capture'!R15) | H14: =IF('Live Capture'!B15="","",'Live Capture'!S15) | I14: =IF('Live Capture'!B15="","",'Live Capture'!W15) | J14: =IF('Live Capture'!B15="","",'Live Capture'!Y15)
A15: =IF('Live Capture'!B16="","",'Live Capture'!B16) | B15: =IF('Live Capture'!B16="","",'Live Capture'!E16) | C15: =IF('Live Capture'!B16="","",'Live Capture'!F16) | D15: =IF('Live Capture'!B16="","",'Live Capture'!I16) | E15: =IF('Live Capture'!B16="","",'Live Capture'!O16) | F15: =IF('Live Capture'!B16="","",'Live Capture'!P16) | G15: =IF('Live Capture'!B16="","",'Live Capture'!R16) | H15: =IF('Live Capture'!B16="","",'Live Capture'!S16) | I15: =IF('Live Capture'!B16="","",'Live Capture'!W16) | J15: =IF('Live Capture'!B16="","",'Live Capture'!Y16)
A16: =IF('Live Capture'!B17="","",'Live Capture'!B17) | B16: =IF('Live Capture'!B17="","",'Live Capture'!E17) | C16: =IF('Live Capture'!B17="","",'Live Capture'!F17) | D16: =IF('Live Capture'!B17="","",'Live Capture'!I17) | E16: =IF('Live Capture'!B17="","",'Live Capture'!O17) | F16: =IF('Live Capture'!B17="","",'Live Capture'!P17) | G16: =IF('Live Capture'!B17="","",'Live Capture'!R17) | H16: =IF('Live Capture'!B17="","",'Live Capture'!S17) | I16: =IF('Live Capture'!B17="","",'Live Capture'!W17) | J16: =IF('Live Capture'!B17="","",'Live Capture'!Y17)
... A504: =IF('Live Capture'!B505="","",'Live Capture'!B505) | B504: =IF('Live Capture'!B505="","",'Live Capture'!E505) | C504: =IF('Live Capture'!B505="","",'Live Capture'!F505) | D504: =IF('Live Capture'!B505="","",'Live Capture'!I505) | E504: =IF('Live Capture'!B505="","",'Live Capture'!O505) | F504: =IF('Live Capture'!B505="","",'Live Capture'!P505) | G504: =IF('Live Capture'!B505="","",'Live Capture'!R505) | H504: =IF('Live Capture'!B505="","",'Live Capture'!S505) | I504: =IF('Live Capture'!B505="","",'Live Capture'!W505) | J504: =IF('Live Capture'!B505="","",'Live Capture'!Y505)

Sheet Follow-Up Engine
A1: Follow-Up Engine
A2: Use this after each conversation. Same-day recap goes out the day of the meeting, next-step ask within 24 hours, and Primo / proof follow-up within 48 hours unless the prospect asks for something else.
A3: Template library: Follow-Up Templates tab | Meeting source: Meetings tab
A5: Capture ID | B5: Account | C5: Persona | D5: Logged At | E5: Band | F5: Due Date | G5: Follow-Up Due | H5: Asset to Send | I5: Template | J5: Owner | K5: Status | L5: Next Step | M5: Notes
A6: =IF('Live Capture'!A6="","",'Live Capture'!A6) -> LC-001 | B6: =IF(A6="","",'Live Capture'!E6) -> Danone | C6: =IF(A6="","",'Live Capture'!F6) -> Test Contact | D6: =IF(A6="","",'Live Capture'!B6) -> 46106.495 | E6: =IF(A6="","",'Live Capture'!W6) -> HOT | F6: =IF(A6="","",'Live Capture'!S6) -> 46107 | G6: =IF(A6="","",IF(F6<>"",F6,INT(D6)+IF(E6="HOT",0,IF(E6="WARM",1,IF(E6="WORK",2,5))))) -> 46107 | H6: =IF(A6="","",IF('Live Capture'!O6<>"",'Live Capture'!O6,"Leave-behind + infographic")) -> Infographic | I6: =IF(A6="","",IF('Live Capture'!T6<>"",'Live Capture'!T6,IF(E6="HOT","Post-meeting strong interest",IF(E6="WARM","Post-meeting standard","Post-meeting light")))) -> Post-meeting strong interest | J6: =IF(A6="","",'Live Capture'!R6) -> Jake | K6: =IF(A6="","",IF('Live Capture'!X6<>"",'Live Capture'!X6,"Open")) -> Open | L6: =IF(A6="","",'Live Capture'!Q6) -> Send Danone Infographic | M6: =IF(A6="","",'Live Capture'!Y6) -> Test submission from setup validation
A7: =IF('Live Capture'!A7="","",'Live Capture'!A7) | B7: =IF(A7="","",'Live Capture'!E7) | C7: =IF(A7="","",'Live Capture'!F7) | D7: =IF(A7="","",'Live Capture'!B7) | E7: =IF(A7="","",'Live Capture'!W7) | F7: =IF(A7="","",'Live Capture'!S7) | G7: =IF(A7="","",IF(F7<>"",F7,INT(D7)+IF(E7="HOT",0,IF(E7="WARM",1,IF(E7="WORK",2,5))))) | H7: =IF(A7="","",IF('Live Capture'!O7<>"",'Live Capture'!O7,"Leave-behind + infographic")) | I7: =IF(A7="","",IF('Live Capture'!T7<>"",'Live Capture'!T7,IF(E7="HOT","Post-meeting strong interest",IF(E7="WARM","Post-meeting standard","Post-meeting light")))) | J7: =IF(A7="","",'Live Capture'!R7) | K7: =IF(A7="","",IF('Live Capture'!X7<>"",'Live Capture'!X7,"Open")) | L7: =IF(A7="","",'Live Capture'!Q7) | M7: =IF(A7="","",'Live Capture'!Y7)
A8: =IF('Live Capture'!A8="","",'Live Capture'!A8) | B8: =IF(A8="","",'Live Capture'!E8) | C8: =IF(A8="","",'Live Capture'!F8) | D8: =IF(A8="","",'Live Capture'!B8) | E8: =IF(A8="","",'Live Capture'!W8) | F8: =IF(A8="","",'Live Capture'!S8) | G8: =IF(A8="","",IF(F8<>"",F8,INT(D8)+IF(E8="HOT",0,IF(E8="WARM",1,IF(E8="WORK",2,5))))) | H8: =IF(A8="","",IF('Live Capture'!O8<>"",'Live Capture'!O8,"Leave-behind + infographic")) | I8: =IF(A8="","",IF('Live Capture'!T8<>"",'Live Capture'!T8,IF(E8="HOT","Post-meeting strong interest",IF(E8="WARM","Post-meeting standard","Post-meeting light")))) | J8: =IF(A8="","",'Live Capture'!R8) | K8: =IF(A8="","",IF('Live Capture'!X8<>"",'Live Capture'!X8,"Open")) | L8: =IF(A8="","",'Live Capture'!Q8) | M8: =IF(A8="","",'Live Capture'!Y8)
A9: =IF('Live Capture'!A9="","",'Live Capture'!A9) | B9: =IF(A9="","",'Live Capture'!E9) | C9: =IF(A9="","",'Live Capture'!F9) | D9: =IF(A9="","",'Live Capture'!B9) | E9: =IF(A9="","",'Live Capture'!W9) | F9: =IF(A9="","",'Live Capture'!S9) | G9: =IF(A9="","",IF(F9<>"",F9,INT(D9)+IF(E9="HOT",0,IF(E9="WARM",1,IF(E9="WORK",2,5))))) | H9: =IF(A9="","",IF('Live Capture'!O9<>"",'Live Capture'!O9,"Leave-behind + infographic")) | I9: =IF(A9="","",IF('Live Capture'!T9<>"",'Live Capture'!T9,IF(E9="HOT","Post-meeting strong interest",IF(E9="WARM","Post-meeting standard","Post-meeting light")))) | J9: =IF(A9="","",'Live Capture'!R9) | K9: =IF(A9="","",IF('Live Capture'!X9<>"",'Live Capture'!X9,"Open")) | L9: =IF(A9="","",'Live Capture'!Q9) | M9: =IF(A9="","",'Live Capture'!Y9)
A10: =IF('Live Capture'!A10="","",'Live Capture'!A10) | B10: =IF(A10="","",'Live Capture'!E10) | C10: =IF(A10="","",'Live Capture'!F10) | D10: =IF(A10="","",'Live Capture'!B10) | E10: =IF(A10="","",'Live Capture'!W10) | F10: =IF(A10="","",'Live Capture'!S10) | G10: =IF(A10="","",IF(F10<>"",F10,INT(D10)+IF(E10="HOT",0,IF(E10="WARM",1,IF(E10="WORK",2,5))))) | H10: =IF(A10="","",IF('Live Capture'!O10<>"",'Live Capture'!O10,"Leave-behind + infographic")) | I10: =IF(A10="","",IF('Live Capture'!T10<>"",'Live Capture'!T10,IF(E10="HOT","Post-meeting strong interest",IF(E10="WARM","Post-meeting standard","Post-meeting light")))) | J10: =IF(A10="","",'Live Capture'!R10) | K10: =IF(A10="","",IF('Live Capture'!X10<>"",'Live Capture'!X10,"Open")) | L10: =IF(A10="","",'Live Capture'!Q10) | M10: =IF(A10="","",'Live Capture'!Y10)
A11: =IF('Live Capture'!A11="","",'Live Capture'!A11) | B11: =IF(A11="","",'Live Capture'!E11) | C11: =IF(A11="","",'Live Capture'!F11) | D11: =IF(A11="","",'Live Capture'!B11) | E11: =IF(A11="","",'Live Capture'!W11) | F11: =IF(A11="","",'Live Capture'!S11) | G11: =IF(A11="","",IF(F11<>"",F11,INT(D11)+IF(E11="HOT",0,IF(E11="WARM",1,IF(E11="WORK",2,5))))) | H11: =IF(A11="","",IF('Live Capture'!O11<>"",'Live Capture'!O11,"Leave-behind + infographic")) | I11: =IF(A11="","",IF('Live Capture'!T11<>"",'Live Capture'!T11,IF(E11="HOT","Post-meeting strong interest",IF(E11="WARM","Post-meeting standard","Post-meeting light")))) | J11: =IF(A11="","",'Live Capture'!R11) | K11: =IF(A11="","",IF('Live Capture'!X11<>"",'Live Capture'!X11,"Open")) | L11: =IF(A11="","",'Live Capture'!Q11) | M11: =IF(A11="","",'Live Capture'!Y11)
A12: =IF('Live Capture'!A12="","",'Live Capture'!A12) | B12: =IF(A12="","",'Live Capture'!E12) | C12: =IF(A12="","",'Live Capture'!F12) | D12: =IF(A12="","",'Live Capture'!B12) | E12: =IF(A12="","",'Live Capture'!W12) | F12: =IF(A12="","",'Live Capture'!S12) | G12: =IF(A12="","",IF(F12<>"",F12,INT(D12)+IF(E12="HOT",0,IF(E12="WARM",1,IF(E12="WORK",2,5))))) | H12: =IF(A12="","",IF('Live Capture'!O12<>"",'Live Capture'!O12,"Leave-behind + infographic")) | I12: =IF(A12="","",IF('Live Capture'!T12<>"",'Live Capture'!T12,IF(E12="HOT","Post-meeting strong interest",IF(E12="WARM","Post-meeting standard","Post-meeting light")))) | J12: =IF(A12="","",'Live Capture'!R12) | K12: =IF(A12="","",IF('Live Capture'!X12<>"",'Live Capture'!X12,"Open")) | L12: =IF(A12="","",'Live Capture'!Q12) | M12: =IF(A12="","",'Live Capture'!Y12)
A13: =IF('Live Capture'!A13="","",'Live Capture'!A13) | B13: =IF(A13="","",'Live Capture'!E13) | C13: =IF(A13="","",'Live Capture'!F13) | D13: =IF(A13="","",'Live Capture'!B13) | E13: =IF(A13="","",'Live Capture'!W13) | F13: =IF(A13="","",'Live Capture'!S13) | G13: =IF(A13="","",IF(F13<>"",F13,INT(D13)+IF(E13="HOT",0,IF(E13="WARM",1,IF(E13="WORK",2,5))))) | H13: =IF(A13="","",IF('Live Capture'!O13<>"",'Live Capture'!O13,"Leave-behind + infographic")) | I13: =IF(A13="","",IF('Live Capture'!T13<>"",'Live Capture'!T13,IF(E13="HOT","Post-meeting strong interest",IF(E13="WARM","Post-meeting standard","Post-meeting light")))) | J13: =IF(A13="","",'Live Capture'!R13) | K13: =IF(A13="","",IF('Live Capture'!X13<>"",'Live Capture'!X13,"Open")) | L13: =IF(A13="","",'Live Capture'!Q13) | M13: =IF(A13="","",'Live Capture'!Y13)
A14: =IF('Live Capture'!A14="","",'Live Capture'!A14) | B14: =IF(A14="","",'Live Capture'!E14) | C14: =IF(A14="","",'Live Capture'!F14) | D14: =IF(A14="","",'Live Capture'!B14) | E14: =IF(A14="","",'Live Capture'!W14) | F14: =IF(A14="","",'Live Capture'!S14) | G14: =IF(A14="","",IF(F14<>"",F14,INT(D14)+IF(E14="HOT",0,IF(E14="WARM",1,IF(E14="WORK",2,5))))) | H14: =IF(A14="","",IF('Live Capture'!O14<>"",'Live Capture'!O14,"Leave-behind + infographic")) | I14: =IF(A14="","",IF('Live Capture'!T14<>"",'Live Capture'!T14,IF(E14="HOT","Post-meeting strong interest",IF(E14="WARM","Post-meeting standard","Post-meeting light")))) | J14: =IF(A14="","",'Live Capture'!R14) | K14: =IF(A14="","",IF('Live Capture'!X14<>"",'Live Capture'!X14,"Open")) | L14: =IF(A14="","",'Live Capture'!Q14) | M14: =IF(A14="","",'Live Capture'!Y14)
